<?xml version="1.0" encoding="utf-8"?>
<robot name="diff_drive_robot">
  <link name="base_footprint" />

  <link name="base_link">
    <inertial>
      <origin xyz="-0.00645691832708175 0.00012687627285592 0.0184393057752323" rpy="0 0 0" />
      <mass value="3.944486750636" />
      <inertia
        ixx="0.0483033035830139"
        ixy="-1.91394645543225E-07"
        ixz="9.73072511268194E-05"
        iyy="0.077628979468859"
        iyz="2.45193366265305E-07"
        izz="0.120885604933525" />
    </inertial>
    <visual>
      <origin xyz="0 0 0" rpy="0 0 0" />
      <geometry>
        <mesh filename="package://diff_drive_robot/meshes/base_link.STL" />
      </geometry>
      <material name="">
        <color rgba="0.792156862745098 0.819607843137255 0.933333333333333 1" />
      </material>
    </visual>
    <collision>
      <origin xyz="0 0 0" rpy="0 0 0" />
      <geometry>
        <mesh filename="package://diff_drive_robot/meshes/base_link.STL" />
      </geometry>
    </collision>
  </link>

  <joint name="base_joint" type="fixed">
    <origin xyz="0 0 0.1" rpy="-1.57 0 0"/>
    <parent link="base_footprint"/>
    <child link="base_link"/>
  </joint>

  <link name="left_wheel">
    <inertial>
      <origin xyz="2.85924710320992E-16 2.42861286636753E-17 0.33239616244097" rpy="0 0 0" />
      <mass value="0.669795771787872" />
      <inertia
        ixx="0.001953475767812"
        ixy="-1.05110098931055E-20"
        ixz="7.02831194139743E-20"
        iyy="0.001953475767812"
        iyz="9.86008147363709E-20"
        izz="0.00371292723221973" />
    </inertial>
    <visual>
      <origin xyz="0 0 0" rpy="0 0 0" />
      <geometry>
        <mesh filename="package://diff_drive_robot/meshes/left_wheel.STL" />
      </geometry>
      <material name="">
        <color rgba="0.792156862745098 0.819607843137255 0.933333333333333 1" />
      </material>
    </visual>
    <collision>
      <origin xyz="0 0 0" rpy="0 0 0" />
      <geometry>
        <mesh filename="package://diff_drive_robot/meshes/left_wheel.STL" />
      </geometry>
    </collision>
  </link>
  
  <joint name="left_wheel_joint" type="revolute">
    <origin xyz="0 0.02 0.166" rpy="3.1416 0 0" />
    <parent link="base_link" />
    <child link="left_wheel" />
    <axis xyz="0 0 1" />
    <limit lower="-3.14" upper="3.14" effort="1.0" velocity="3.14" />
  </joint>
  
  <link name="right_wheel">
    <inertial>
      <origin xyz="-2.94638503968529E-16 2.77555756156289E-17 0.33239616244097" rpy="0 0 0" />
      <mass value="0.669795771787873" />
      <inertia
        ixx="0.001953475767812"
        ixy="-5.77733959080005E-20"
        ixz="-4.06766603001359E-20"
        iyy="0.001953475767812"
        iyz="-8.62641631893792E-19"
        izz="0.00371292723221973" />
    </inertial>
    <visual>
      <origin xyz="0 0 0" rpy="0 0 0" />
      <geometry>
        <mesh filename="package://diff_drive_robot/meshes/right_wheel.STL" />
      </geometry>
      <material name="">
        <color rgba="0.792156862745098 0.819607843137255 0.933333333333333 1" />
      </material>
    </visual>
    <collision>
      <origin xyz="0 0 0" rpy="0 0 0" />
      <geometry>
        <mesh filename="package://diff_drive_robot/meshes/right_wheel.STL" />
      </geometry>
    </collision>
  </link>
  
  <joint name="right_wheel_joint" type="revolute">
    <origin xyz="0 0.02 -0.166" rpy="0 0 0" />
    <parent link="base_link" />
    <child link="right_wheel" />
    <axis xyz="0 0 1" />
    <limit lower="-3.14" upper="3.14" effort="1.0" velocity="3.14" />
  </joint>

  <link name="lidar_link">
    <visual>
      <geometry>
        <cylinder length="0.05" radius="0.08"/>
      </geometry>
      <material name="blue">
        <color rgba="0 0.5 1 0.8"/>
      </material>
    </visual>
    <collision>
      <geometry>
        <cylinder length="0.005" radius="0.004"/>
      </geometry>
    </collision>
    <inertial>
      <mass value="0.1"/>
      <inertia 
        ixx="0.001" ixy="0" ixz="0"
        iyy="0.001" iyz="0"
        izz="0.001"/>
         </inertial>
  </link>

  <joint name="lidar_joint" type="fixed">
    <parent link="base_link"/>
    <child link="lidar_link"/>
    <origin xyz="0.2 -0.1 0" rpy="1.57 0 0"/>
  </joint>
  
  <!-- 1. CAN接口 - 用于CAN总线电机控制器 -->
  <ros2_control name="DiffDriveSystemCAN" type="system">
    <hardware>
      <plugin>diff_drive_robot/CanHardwareInterface</plugin>
      <param name="can_interface">can0</param>
      <param name="can_bitrate">1000000</param>
      <param name="left_wheel_id">21</param>
      <param name="right_wheel_id">22</param>
    </hardware>
    <joint name="left_wheel_joint">
      <command_interface name="velocity"/>
      <state_interface name="position"/>
      <state_interface name="velocity"/>
    </joint>
    <joint name="right_wheel_joint">
      <command_interface name="velocity"/>
      <state_interface name="position"/>
      <state_interface name="velocity"/>
    </joint>
  </ros2_control>
  

  
  <!-- Gazebo相关配置 -->
  <gazebo>
    <plugin name="diff_drive" filename="libgazebo_ros_diff_drive.so">
      <left_joint>left_wheel_joint</left_joint>
      <right_joint>right_wheel_joint</right_joint>
      <wheel_separation>0.332</wheel_separation>
      <wheel_diameter>0.1</wheel_diameter>
      <max_wheel_acceleration>10.0</max_wheel_acceleration>
      <max_wheel_torque>20</max_wheel_torque>
      <publish_odom>true</publish_odom>
      <publish_odom_tf>true</publish_odom_tf>
      <publish_wheel_tf>true</publish_wheel_tf>
      <odometry_frame>odom</odometry_frame>
      <robot_base_frame>base_link</robot_base_frame>
    </plugin>
  </gazebo>
  
  <!-- LiDAR的Gazebo配置 -->
  <gazebo reference="lidar_link">
    <sensor type="ray" name="lidar">
      <pose>0 0 0 0 0 0</pose>
      <visualize>true</visualize>
      <update_rate>10</update_rate>
      <ray>
        <scan>
          <horizontal>
            <samples>360</samples>
            <resolution>1</resolution>
            <min_angle>-3.14159</min_angle>
            <max_angle>3.14159</max_angle>
          </horizontal>
        </scan>
        <range>
          <min>0.1</min>
          <max>10.0</max>
          <resolution>0.01</resolution>
        </range>
        <noise>
          <type>gaussian</type>
          <mean>0.0</mean>
          <stddev>0.01</stddev>
        </noise>
      </ray>
      <plugin name="gazebo_ros_lidar_controller" filename="libgazebo_ros_ray_sensor.so">
        <ros>
          <namespace>/</namespace>
          <remapping>~/out:=scan</remapping>
        </ros>
        <output_type>sensor_msgs/LaserScan</output_type>
        <frame_name>lidar_link</frame_name>
      </plugin>
    </sensor>
  </gazebo>
</robot>